[2024-06-12T07:08:05.780+0000] {taskinstance.py:1083} INFO - Dependencies all met for <TaskInstance: api_to_s3_to_redshift.upload_to_s3 manual__2024-06-12T07:07:51.969986+00:00 [queued]>
[2024-06-12T07:08:05.821+0000] {taskinstance.py:1083} INFO - Dependencies all met for <TaskInstance: api_to_s3_to_redshift.upload_to_s3 manual__2024-06-12T07:07:51.969986+00:00 [queued]>
[2024-06-12T07:08:05.822+0000] {taskinstance.py:1279} INFO - 
--------------------------------------------------------------------------------
[2024-06-12T07:08:05.822+0000] {taskinstance.py:1280} INFO - Starting attempt 1 of 2
[2024-06-12T07:08:05.823+0000] {taskinstance.py:1281} INFO - 
--------------------------------------------------------------------------------
[2024-06-12T07:08:05.886+0000] {taskinstance.py:1300} INFO - Executing <Task(LocalFilesystemToS3Operator): upload_to_s3> on 2024-06-12 07:07:51.969986+00:00
[2024-06-12T07:08:05.902+0000] {standard_task_runner.py:55} INFO - Started process 4388 to run task
[2024-06-12T07:08:05.909+0000] {standard_task_runner.py:82} INFO - Running: ['***', 'tasks', 'run', 'api_to_s3_to_redshift', 'upload_to_s3', 'manual__2024-06-12T07:07:51.969986+00:00', '--job-id', '5', '--raw', '--subdir', 'DAGS_FOLDER/test_redshift_real.py', '--cfg-path', '/tmp/tmpazzkxllp']
[2024-06-12T07:08:05.911+0000] {standard_task_runner.py:83} INFO - Job 5: Subtask upload_to_s3
[2024-06-12T07:08:06.128+0000] {task_command.py:388} INFO - Running <TaskInstance: api_to_s3_to_redshift.upload_to_s3 manual__2024-06-12T07:07:51.969986+00:00 [running]> on host be394f3a6896
[2024-06-12T07:08:06.733+0000] {taskinstance.py:1509} INFO - Exporting the following env vars:
AIRFLOW_CTX_DAG_OWNER=***
AIRFLOW_CTX_DAG_ID=api_to_s3_to_redshift
AIRFLOW_CTX_TASK_ID=upload_to_s3
AIRFLOW_CTX_EXECUTION_DATE=2024-06-12T07:07:51.969986+00:00
AIRFLOW_CTX_TRY_NUMBER=1
AIRFLOW_CTX_DAG_RUN_ID=manual__2024-06-12T07:07:51.969986+00:00
[2024-06-12T07:08:06.811+0000] {base.py:73} INFO - Using connection ID 'aws_s3' for task execution.
[2024-06-12T07:08:06.813+0000] {connection_wrapper.py:334} INFO - AWS Connection (conn_id='aws_s3', conn_type='aws') credentials retrieved from login and password.
[2024-06-12T07:08:08.997+0000] {taskinstance.py:1768} ERROR - Task failed with exception
Traceback (most recent call last):
  File "/home/airflow/.local/lib/python3.7/site-packages/airflow/providers/amazon/aws/transfers/local_to_s3.py", line 107, in execute
    self.acl_policy,
  File "/home/airflow/.local/lib/python3.7/site-packages/airflow/providers/amazon/aws/hooks/s3.py", line 99, in wrapper
    return func(*bound_args.args, **bound_args.kwargs)
  File "/home/airflow/.local/lib/python3.7/site-packages/airflow/providers/amazon/aws/hooks/s3.py", line 70, in wrapper
    return func(*bound_args.args, **bound_args.kwargs)
  File "/home/airflow/.local/lib/python3.7/site-packages/airflow/providers/amazon/aws/hooks/s3.py", line 631, in load_file
    raise ValueError(f"The key {key} already exists.")
ValueError: The key dataSource/api_data.csv already exists.
[2024-06-12T07:08:09.021+0000] {taskinstance.py:1323} INFO - Marking task as UP_FOR_RETRY. dag_id=api_to_s3_to_redshift, task_id=upload_to_s3, execution_date=20240612T070751, start_date=20240612T070805, end_date=20240612T070809
[2024-06-12T07:08:09.064+0000] {standard_task_runner.py:105} ERROR - Failed to execute job 5 for task upload_to_s3 (The key dataSource/api_data.csv already exists.; 4388)
[2024-06-12T07:08:09.125+0000] {local_task_job.py:208} INFO - Task exited with return code 1
[2024-06-12T07:08:09.207+0000] {taskinstance.py:2578} INFO - 0 downstream tasks scheduled from follow-on schedule check
